Workbook
Name 수용여부: [1]범례!$I$7:$I$12
Name 요구구분: [1]범례!$F$7:$F$10
Name 협의상태: [1]범례!$D$7:$D$11

Sheet 표지
B4: 소비데이터 분석 서비스
B8: WBS
F40: 문서 ID | G40: 소비데이터 분석 서비스 WBS
F41: 버 전 | G41: v1.3
F42: 작 성 일 | G42: 46106
F43: 작 성 자 | G43: 김인호

Sheet 개정이력
B1: 문서개정이력
B4: NO | C4: 버전 | D4: 날짜 | E4: 개정사유(1) | F4: 개정내역(2) | G4: 작성자
B5: 1 | C5: 1 | D5: 46029 | E5: 제정 | F5: 초안작성 | G5: 이상인
B6: 2 | C6: 1.1 | D6: 46050 | E6: 신규 | F6: 업무별 테스크 추가 | G6: 김인호
B7: 3 | C7: 1.2 | D7: 46091 | E7: 신규 | F7: 업무별 테스크 추가 | G7: 김인호
B8: 4 | C8: 1.3 | D8: 46106 | E8: 추가 | F8: 시루정보 업무 일정 반영 | G8: 김인호
B9: 5
B10: 6
B11: 7
B12: 8
B13: 9
B14: 10
B15: 11
B16: 12
B17: 13
B18: 14
B20: (1)내용 : 개정이 발생하는 페이지 번호와 변경 내용을 기술

Sheet WBS_선행개발
M4: 진척 현황판 ※ SPI : Schedule Perfomance Index : 일정성과지표
M5: 진척신호 | N5: =IF(Y5>=95%,"양호",IF(AND(Y5>=90%,Y5<95%),"보통",IF(Y5<90%,"미흡",""))) -> 미흡 | O5: 달성율 | P5: 달성율 | Q5: =W5/U5 -> 0.54469826 | R5: *기준일자 | S5: 46120 | T5: 계획진척 | U5: =R9 -> 0.22319697 | V5: 실제진척 | W5: =U9 -> 0.121575 | X5: SPI | Y5: =IFERROR(X9/W9,"") -> 0.54469826
B7: No | C7: WBS Code | D7: Dep | E7: 작업명 | L7: 계획 | S7: 실적 | V7: 업무 구성비 | W7: 구성진행비율 | AA7: 비고(산출물-예정)
L8: 기간 | M8: 시작일 | N8: 종료일 | O8: 총괄 | P8: 수행사 | Q8: 담당자 | R8: 진척율 | S8: 시작일 | T8: 종료일 | U8: 진척율 | W8: 계획 | X8: 실적 | Y8: 잔여일 | Z8: 차
B9: 0 | C9: Project | D9: 0 | E9: ONDA 프로젝트 | L9: =CONCATENATE(NETWORKDAYS(M9,N9,holiday!B$4:B$20),"일") -> 209일 | M9: =MIN(M10,M18,M104,M221,M262) -> 46076 | N9: =MAX(N10,N18,N104,N221,N262) -> 46374 | O9: 한국조폐공사 | P9: 한국조폐공사 | Q9: 이상인 | R9: =SUM(W10,W18,W104,W221,W262) -> 0.22319697 | S9: =IF(COUNT(T10:T285)>0,MIN(T10:T285),"") -> 46101 | T9: =IF(COUNT(T10:T285)>0,MAX(T10:T285),"") -> 46112 | U9: =SUM(X10,X18,X104,X221,X262) -> 0.121575 | V9: 1 | W9: =R9*V9 -> 0.22319697 | X9: =U9*V9 -> 0.121575 | Y9: =IF(N9-$S$5<=0,0,CONCATENATE(NETWORKDAYS($S$5,N9,holiday!$B$4:$B$20))) -> 178 | Z9: =IF(SUM(W9:X9)>0,(X9-W9)/V9,0) -> -0.10162197
B10: 1 | C10: Project 1 | D10: 1 | F10: 프로젝트관리 | L10: =CONCATENATE(NETWORKDAYS(M10,N10,holiday!B$4:B$20),"일") -> 89일 | M10: =MIN(M11,M13,M15) -> 46076 | N10: =MAX(N11,N13,N15) -> 46203 | O10: 한국조폐공사 | P10: 한국조폐공사 | Q10: 이상인 | R10: =SUM(W11,W13,W15) -> 0.29483696 | S10: =IF(COUNT(S11:S17)>0,MIN(S11:S17),"") -> 46076 | T10: =IF(COUNT(T11:T17)>0,MAX(T11:T17),"") | U10: =SUM(X11,X13,X15) -> 0.13125 | V10: 0.1 | W10: =R10*V10 -> 0.029483696 | X10: =U10*V10 -> 0.013125 | Y10: =IF(N10-$S$5<=0,0,CONCATENATE(NETWORKDAYS($S$5,N10,holiday!$B$4:$B$20))) -> 58 | Z10: =IF(SUM(W10:X10)>0,(X10-W10)/V10,0) -> -0.16358696
B11: 2 | C11: Project 1.2 | D11: 2 | G11: 프로젝트계획수립 | L11: =CONCATENATE(NETWORKDAYS(M11,N11,holiday!B$4:B$20),"일") -> 14일 | M11: =MIN(M12) -> 46084 | N11: =MAX(N12) -> 46101 | O11: 한국조폐공사 | P11: 한국조폐공사 | Q11: 이상인 | R11: =SUM(W12) -> 0.5 | S11: 46076 | U11: =SUM(X12) -> 0.4 | V11: 0.25 | W11: =R11*V11 -> 0.125 | X11: =U11*V11 -> 0.1 | Y11: =IF(N11-$S$5<=0,0,CONCATENATE(NETWORKDAYS($S$5,N11,holiday!$B$4:$B$20))) -> 0 | Z11: =IF(SUM(W11:X11)>0,(X11-W11)/V11,0) -> -0.1
B12: 3 | C12: Project 1.2.1 | D12: 3 | H12: 사업수행계획수립 | L12: =CONCATENATE(NETWORKDAYS(M12,N12,holiday!B$4:B$20),"일") -> 14일 | M12: 46084 | N12: 46101 | O12: 한국조폐공사 | P12: 한국조폐공사 | Q12: 이상인 | R12: =IF(COUNTBLANK(M12:N12)>0,0,1/NETWORKDAYS(M12,N12)*(IF($S$5<=M12,0,NETWORKDAYS(M12,IF($S$5>N12,N12,$S$5))))) -> 1 | S12: 46179 | U12: 0.8 | V12: =0.5 -> 0.5 | W12: =R12*V12 -> 0.5 | X12: =U12*V12 -> 0.4 | Y12: =IF(N12-$S$5<=0,0,CONCATENATE(NETWORKDAYS($S$5,N12,holiday!$B$4:$B$20))) -> 0 | Z12: =IF(SUM(W12:X12)>0,(X12-W12)/V12,0) -> -0.2 | AA12: 사업수행계획서
B13: 4 | C13: Project 1.2 | D13: 2 | G13: 의사소통관리 | L13: =CONCATENATE(NETWORKDAYS(M13,N13,holiday!B$4:B$20),"일") -> 89일 | M13: =MIN(M14:M14) -> 46076 | N13: =MAX(N14:N14) -> 46203 | O13: 한국조폐공사 | P13: 한국조폐공사 | Q13: 이상인 | R13: =SUM(W14:W14) -> 0.17934783 | S13: 46076 | U13: =SUM(X14:X14) -> 0.125 | V13: 0.25 | W13: =R13*V13 -> 0.044836957 | X13: =U13*V13 -> 0.03125 | Y13: 0 | Z13: 0
B14: 5 | C14: Project 1.2.1 | D14: 3 | H14: 주간업무보고 | L14: =CONCATENATE(NETWORKDAYS(M14,N14,holiday!B$4:B$20),"일") -> 89일 | M14: 46076 | N14: 46203 | O14: 한국조폐공사 | P14: 한국조폐공사 | Q14: 이상인 | R14: =IF(COUNTBLANK(M14:N14)>0,0,1/NETWORKDAYS(M14,N14)*(IF($S$5<=M14,0,NETWORKDAYS(M14,IF($S$5>N14,N14,$S$5))))) -> 0.35869565 | S14: 46076 | U14: 0.25 | V14: =0.5 -> 0.5 | W14: =R14*V14 -> 0.17934783 | X14: =U14*V14 -> 0.125 | Y14: =IF(N14-$S$5<=0,0,CONCATENATE(NETWORKDAYS($S$5,N14,holiday!$B$4:$B$20))) -> 58 | Z14: =IF(SUM(W14:X14)>0,(X14-W14)/V14,0) -> -0.10869565 | AA14: 주간보고서
B15: 6 | C15: Project 1.3 | D15: 2 | G15: 프로젝트마감활동 | L15: =CONCATENATE(NETWORKDAYS(M15,N15,holiday!B$4:B$20),"일") -> 32일 | M15: =MIN(M16:M17) -> 46113 | N15: =MAX(N16:N17) -> 46157 | O15: 한국조폐공사 | P15: 한국조폐공사 | Q15: 이상인 | R15: =SUM(W16:W17) -> 0.25 | U15: =SUM(X16:X17) -> 0 | V15: 0.5 | W15: =R15*V15 -> 0.125 | X15: =U15*V15 -> 0 | Y15: =IF(N15-$S$5<=0,0,CONCATENATE(NETWORKDAYS($S$5,N15,holiday!$B$4:$B$20))) -> 27 | Z15: =IF(SUM(W15:X15)>0,(X15-W15)/V15,0) -> -0.25
B16: 7 | C16: Project 1.3.1 | D16: 3 | H16: 착수보고 | L16: =CONCATENATE(NETWORKDAYS(M16,N16,holiday!B$4:B$20),"일") -> 1일 | M16: 46113 | N16: 46113 | O16: 한국조폐공사 | P16: 한국조폐공사 | Q16: 이상인 | R16: =IF(COUNTBLANK(M16:N16)>0,0,1/NETWORKDAYS(M16,N16)*(IF($S$5<=M16,0,NETWORKDAYS(M16,IF($S$5>N16,N16,$S$5))))) -> 1 | U16: 0 | V16: 0.25 | W16: =R16*V16 -> 0.25 | X16: =U16*V16 -> 0 | Y16: =IF(N16-$S$5<=0,0,CONCATENATE(NETWORKDAYS($S$5,N16,holiday!$B$4:$B$20))) -> 0 | Z16: =IF(SUM(W16:X16)>0,(X16-W16)/V16,0) -> -1 | AA16: 착수보고서
B17: 8 | C17: Project 1.3.2 | D17: 3 | H17: 중간보고(프로토타입 시연) | L17: =CONCATENATE(NETWORKDAYS(M17,N17,holiday!B$4:B$20),"일") -> 1일 | M17: 46157 | N17: 46157 | O17: 한국조폐공사 | P17: 한국조폐공사 | Q17: 이상인 | R17: =IF(COUNTBLANK(M17:N17)>0,0,1/NETWORKDAYS(M17,N17)*(IF($S$5<=M17,0,NETWORKDAYS(M17,IF($S$5>N17,N17,$S$5))))) -> 0 | U17: 0 | V17: 0.25 | W17: =R17*V17 -> 0 | X17: =U17*V17 -> 0 | Y17: =IF(N17-$S$5<=0,0,CONCATENATE(NETWORKDAYS($S$5,N17,holiday!$B$4:$B$20))) -> 27 | Z17: =IF(SUM(W17:X17)>0,(X17-W17)/V17,0) -> 0 | AA17: 중간보고서
B18: 9 | C18: Project 2 | D18: 1 | F18: 분석/설계 | L18: =CONCATENATE(NETWORKDAYS(M18,N18,holiday!B$4:B$20),"일") -> 73일 | M18: =MIN(M19,M21,M42,M55,M73) -> 46083 | N18: =MAX(N19,N21,N42,N55,N73) -> 46188 | O18: 한국조폐공사 | P18: 한국조폐공사 | Q18: 이상인 | R18: =SUM(W19,W21,W42,W55,W73) -> 0.51982955 | U18: =SUM(X19,X21,X42,X55,X73) -> 0.3615 | V18: 0.3 | W18: =R18*V18 -> 0.15594886 | X18: =U18*V18 -> 0.10845 | Y18: =IF(N18-$S$5<=0,0,CONCATENATE(NETWORKDAYS($S$5,N18,holiday!$B$4:$B$20))) -> 47 | Z18: =IF(SUM(W18:X18)>0,(X18-W18)/V18,0) -> -0.15832955
B19: 10 | C19: Project 2.1 | D19: 2 | G19: 요구사항분석 | L19: =CONCATENATE(NETWORKDAYS(M19,N19,holiday!B$4:B$20),"일") -> 14일 | M19: =MIN(M20) -> 46084 | N19: =MAX(N20) -> 46101 | O19: 한국조폐공사 | P19: 한국조폐공사 | Q19: 이상인 | R19: =SUM(W20) -> 1 | U19: =SUM(X20) -> 1 | V19: 0.1 | W19: =R19*V19 -> 0.1 | X19: =U19*V19 -> 0.1 | Y19: =IF(N19-$S$5<=0,0,CONCATENATE(NETWORKDAYS($S$5,N19,holiday!$B$4:$B$20))) -> 0 | Z19: =IF(SUM(W19:X19)>0,(X19-W19)/V19,0) -> 0
B20: 11 | C20: Project 2.1.1 | D20: 3 | H20: 소상공인 소비데이터 요구사항 분석 | L20: =CONCATENATE(NETWORKDAYS(M20,N20,holiday!B$4:B$20),"일") -> 14일 | M20: 46084 | N20: 46101 | O20: 한국조폐공사 | P20: 한국조폐공사 | Q20: 이상인 | R20: =IF(COUNTBLANK(M20:N20)>0,0,1/NETWORKDAYS(M20,N20,holiday!B$4:B$20)*(IF($S$5<=M20,0,NETWORKDAYS(M20,IF($S$5>N20,N20,$S$5),holiday!B$4:B$20)))) -> 1 | U20: 1 | V20: 1 | W20: =R20*V20 -> 1 | X20: =U20*V20 -> 1 | Y20: =IF(N20-$S$5<=0,0,CONCATENATE(NETWORKDAYS($S$5,N20,holiday!$B$4:$B$20))) -> 0 | Z20: =IF(SUM(W20:X20)>0,(X20-W20)/V20,0) -> 0 | AA20: RFP 요구사항 정의서
B21: 12 | C21: Project 2.3 | D21: 2 | G21: 앱기능 개선(소비자 분석) | L21: =CONCATENATE(NETWORKDAYS(M21,N21,holiday!B$4:B$20),"일") -> 20일 | M21: =MIN(M22,M25,M30,M35) -> 46083 | N21: =MAX(N22,N25,N30,N35) -> 46111 | O21: 한국조폐공사 | P21: 핑거 | Q21: 유효준 | R21: =SUM(W22,W25,W30,W35) -> 0.4975 | U21: =SUM(X22,X25,X30,X35) -> 0.031 | V21: 0.25 | W21: =R21*V21 -> 0.124375 | X21: =U21*V21 -> 0.00775 | Y21: =IF(N21-$S$5<=0,0,CONCATENATE(NETWORKDAYS($S$5,N21,holiday!$B$4:$B$20))) -> 0 | Z21: =IF(SUM(W21:X21)>0,(X21-W21)/V21,0) -> -0.4665
B22: 13 | C22: Project 2.3.1 | D22: 3 | H22: 현황 및 요구사항 분석 | L22: =CONCATENATE(NETWORKDAYS(M22,N22,holiday!B$4:B$20),"일") -> 20일 | M22: =MIN(M23:M24) -> 46083 | N22: =MAX(N23:N24) -> 46111 | O22: 한국조폐공사 | P22: 핑거 | Q22: 유효준 | R22: =SUM(W23:W24) -> 1 | U22: =SUM(X23:X24) -> 0.31 | V22: 0.1 | W22: =R22*V22 -> 0.1 | X22: =U22*V22 -> 0.031 | Y22: =IF(N22-$S$5<=0,0,CONCATENATE(NETWORKDAYS($S$5,N22,holiday!$B$4:$B$20))) -> 0 | Z22: =IF(SUM(W22:X22)>0,(X22-W22)/V22,0) -> -0.69
B23: 14 | C23: Project 2.3.1.1 | D23: 4 | I23: 개선 범위 정의 | L23: =CONCATENATE(NETWORKDAYS(M23,N23,holiday!B$4:B$20),"일") -> 20일 | M23: 46083 | N23: 46111 | O23: 한국조폐공사 | P23: 핑거 | Q23: 유효준 | R23: =IF(COUNTBLANK(M23:N23)>0,0,1/NETWORKDAYS(M23,N23,holiday!B$4:B$20)*(IF($S$5<=M23,0,NETWORKDAYS(M23,IF($S$5>N23,N23,$S$5),holiday!B$4:B$20)))) -> 1 | U23: 0.31 | V23: 0.5 | W23: =R23*V23 -> 0.5 | X23: =U23*V23 -> 0.155 | Y23: =IF(N23-$S$5<=0,0,CONCATENATE(NETWORKDAYS($S$5,N23,holiday!$B$4:$B$20))) -> 0 | Z23: =IF(SUM(W23:X23)>0,(X23-W23)/V23,0) -> -0.69
B24: 15 | C24: Project 2.3.1.2 | D24: 4 | I24: 기존 서비스(AS-IS) 분석 | L24: =CONCATENATE(NETWORKDAYS(M24,N24,holiday!B$4:B$20),"일") -> 20일 | M24: 46083 | N24: 46111 | O24: 한국조폐공사 | P24: 핑거 | Q24: 유효준 | R24: =IF(COUNTBLANK(M24:N24)>0,0,1/NETWORKDAYS(M24,N24,holiday!B$4:B$20)*(IF($S$5<=M24,0,NETWORKDAYS(M24,IF($S$5>N24,N24,$S$5),holiday!B$4:B$20)))) -> 1 | U24: 0.31 | V24: 0.5 | W24: =R24*V24 -> 0.5 | X24: =U24*V24 -> 0.155 | Y24: =IF(N24-$S$5<=0,0,CONCATENATE(NETWORKDAYS($S$5,N24,holiday!$B$4:$B$20))) -> 0 | Z24: =IF(SUM(W24:X24)>0,(X24-W24)/V24,0) -> -0.69
B25: 16 | C25: Project 2.3.2 | D25: 3 | H25: 소비케어 서비스 | L25: =CONCATENATE(NETWORKDAYS(M25,N25,holiday!B$4:B$20),"일") -> 6일 | M25: =MIN(M26,M28,M29) -> 46104 | N25: =MAX(N26,N28,N29) -> 46111 | O25: 한국조폐공사 | P25: 핑거 | Q25: 유효준 | R25: =SUM(W26:W29) -> 1 | U25: =SUM(X26:X29) -> 0 | V25: 0.15 | W25: =R25*V25 -> 0.15 | X25: =U25*V25 -> 0 | Y25: =IF(N25-$S$5<=0,0,CONCATENATE(NETWORKDAYS($S$5,N25,holiday!$B$4:$B$20))) -> 0 | Z25: =IF(SUM(W25:X25)>0,(X25-W25)/V25,0) -> -1
B26: 17 | C26: Project 2.3.2.1 | D26: 4 | I26: 소비내역 UI/UX 개선 화면설계 | L26: =CONCATENATE(NETWORKDAYS(M26,N26,holiday!B$4:B$20),"일") -> 6일 | M26: 46104 | N26: 46111 | O26: 한국조폐공사 | P26: 핑거 | Q26: 유효준 | R26: =IF(COUNTBLANK(M26:N26)>0,0,1/NETWORKDAYS(M26,N26,holiday!B$4:B$20)*(IF($S$5<=M26,0,NETWORKDAYS(M26,IF($S$5>N26,N26,$S$5),holiday!B$4:B$20)))) -> 1 | U26: 0 | V26: 0.25 | W26: =R26*V26 -> 0.25 | X26: =U26*V26 -> 0 | Y26: =IF(N26-$S$5<=0,0,CONCATENATE(NETWORKDAYS($S$5,N26,holiday!$B$4:$B$20))) -> 0 | Z26: =IF(SUM(W26:X26)>0,(X26-W26)/V26,0) -> -1
B27: 18 | C27: Project 2.3.2.2 | I27: 소비케어 서비스 개선 화면 설계 | L27: =CONCATENATE(NETWORKDAYS(M27,N27,holiday!B$4:B$20),"일") -> 6일 | M27: 46104 | N27: 46111 | O27: 한국조폐공사 | P27: 핑거 | Q27: 유효준 | R27: =IF(COUNTBLANK(M27:N27)>0,0,1/NETWORKDAYS(M27,N27)*(IF($S$5<=M27,0,NETWORKDAYS(M27,IF($S$5>N27,N27,$S$5))))) -> 1 | U27: 0 | V27: 0.25 | W27: =R27*V27 -> 0.25 | X27: =U27*V27 -> 0 | Y27: =IF(N27-$S$5<=0,0,CONCATENATE(NETWORKDAYS($S$5,N27,holiday!$B$4:$B$20))) -> 0 | Z27: =IF(SUM(W27:X27)>0,(X27-W27)/V27,0) -> -1
B28: 19 | C28: Project 2.3.2.3 | D28: 4 | I28: 소비패턴 분석 데이터(테이블)/API 설계 | L28: =CONCATENATE(NETWORKDAYS(M28,N28,holiday!B$4:B$20),"일") -> 6일 | M28: 46104 | N28: 46111 | O28: 한국조폐공사 | P28: 핑거 | Q28: 유효준 | R28: =IF(COUNTBLANK(M28:N28)>0,0,1/NETWORKDAYS(M28,N28,holiday!B$4:B$20)*(IF($S$5<=M28,0,NETWORKDAYS(M28,IF($S$5>N28,N28,$S$5),holiday!B$4:B$20)))) -> 1 | U28: 0 | V28: 0.25 | W28: =R28*V28 -> 0.25 | X28: =U28*V28 -> 0 | Y28: =IF(N28-$S$5<=0,0,CONCATENATE(NETWORKDAYS($S$5,N28,holiday!$B$4:$B$20))) -> 0 | Z28: =IF(SUM(W28:X28)>0,(X28-W28)/V28,0) -> -1
B29: 20 | C29: Project 2.3.2.4 | D29: 4 | I29: 소비케어 서비스 프로그램 설계 | L29: =CONCATENATE(NETWORKDAYS(M29,N29,holiday!B$4:B$20),"일") -> 6일 | M29: 46104 | N29: 46111 | O29: 한국조폐공사 | P29: 핑거 | Q29: 유효준 | R29: =IF(COUNTBLANK(M29:N29)>0,0,1/NETWORKDAYS(M29,N29,holiday!B$4:B$20)*(IF($S$5<=M29,0,NETWORKDAYS(M29,IF($S$5>N29,N29,$S$5),holiday!B$4:B$20)))) -> 1 | U29: 0 | V29: 0.25 | W29: =R29*V29 -> 0.25 | X29: =U29*V29 -> 0 | Y29: =IF(N29-$S$5<=0,0,CONCATENATE(NETWORKDAYS($S$5,N29,holiday!$B$4:$B$20))) -> 0 | Z29: =IF(SUM(W29:X29)>0,(X29-W29)/V29,0) -> -1
B30: 21 | C30: Project 2.3.2 | D30: 3 | H30: 지역축제 | L30: =CONCATENATE(NETWORKDAYS(M30,N30,holiday!B$4:B$20),"일") -> 6일 | M30: =MIN(M31,M32,M33,M34) -> 46104 | N30: =MAX(N31,N32,N33,N34) -> 46111 | O30: 한국조폐공사 | P30: 핑거 | Q30: 유효준 | R30: =SUM(W31:W34) -> 1 | U30: =SUM(X31:X34) -> 0 | V30: 0.15 | W30: =R30*V30 -> 0.15 | X30: =U30*V30 -> 0 | Y30: =IF(N30-$S$5<=0,0,CONCATENATE(NETWORKDAYS($S$5,N30,holiday!$B$4:$B$20))) -> 0 | Z30: =IF(SUM(W30:X30)>0,(X30-W30)/V30,0) -> -1
B31: 22 | C31: Project 2.3.2.1 | D31: 4 | I31: 지역축제 UI/UX 개선 화면설계 | L31: =CONCATENATE(NETWORKDAYS(M31,N31,holiday!B$4:B$20),"일") -> 6일 | M31: 46104 | N31: 46111 | O31: 한국조폐공사 | P31: 핑거 | Q31: 유효준 | R31: =IF(COUNTBLANK(M31:N31)>0,0,1/NETWORKDAYS(M31,N31,holiday!B$4:B$20)*(IF($S$5<=M31,0,NETWORKDAYS(M31,IF($S$5>N31,N31,$S$5),holiday!B$4:B$20)))) -> 1 | U31: 0 | V31: 0.25 | W31: =R31*V31 -> 0.25 | X31: =U31*V31 -> 0 | Y31: =IF(N31-$S$5<=0,0,CONCATENATE(NETWORKDAYS($S$5,N31,holiday!$B$4:$B$20))) -> 0 | Z31: =IF(SUM(W31:X31)>0,(X31-W31)/V31,0) -> -1
B32: 23 | C32: Project 2.3.3.1 | D32: 4 | I32: 지역축제 분석 API 설계 | L32: =CONCATENATE(NETWORKDAYS(M32,N32,holiday!B$4:B$20),"일") -> 6일 | M32: 46104 | N32: 46111 | O32: 한국조폐공사 | P32: 핑거 | Q32: 유효준 | R32: =IF(COUNTBLANK(M32:N32)>0,0,1/NETWORKDAYS(M32,N32,holiday!B$4:B$20)*(IF($S$5<=M32,0,NETWORKDAYS(M32,IF($S$5>N32,N32,$S$5),holiday!B$4:B$20)))) -> 1 | U32: 0 | V32: 0.25 | W32: =R32*V32 -> 0.25 | X32: =U32*V32 -> 0 | Y32: =IF(N32-$S$5<=0,0,CONCATENATE(NETWORKDAYS($S$5,N32,holiday!$B$4:$B$20))) -> 0 | Z32: =IF(SUM(W32:X32)>0,(X32-W32)/V32,0) -> -1
B33: 24 | C33: Project 2.3.6.1 | D33: 4 | I33: 지역축제 서비스 인터페이스 설계 | L33: =CONCATENATE(NETWORKDAYS(M33,N33,holiday!B$4:B$20),"일") -> 6일 | M33: 46104 | N33: 46111 | O33: 한국조폐공사 | P33: 핑거 | Q33: 유효준 | R33: =IF(COUNTBLANK(M33:N33)>0,0,1/NETWORKDAYS(M33,N33,holiday!B$4:B$20)*(IF($S$5<=M33,0,NETWORKDAYS(M33,IF($S$5>N33,N33,$S$5),holiday!B$4:B$20)))) -> 1 | U33: 0 | V33: 0.25 | W33: =R33*V33 -> 0.25 | X33: =U33*V33 -> 0 | Y33: =IF(N33-$S$5<=0,0,CONCATENATE(NETWORKDAYS($S$5,N33,holiday!$B$4:$B$20))) -> 0 | Z33: =IF(SUM(W33:X33)>0,(X33-W33)/V33,0) -> -1
B34: 25 | C34: Project 2.3.6.1 | D34: 4 | I34: 지역축제 서비스 프로그램 설계 | L34: =CONCATENATE(NETWORKDAYS(M34,N34,holiday!B$4:B$20),"일") -> 6일 | M34: 46104 | N34: 46111 | O34: 한국조폐공사 | P34: 핑거 | Q34: 유효준 | R34: =IF(COUNTBLANK(M34:N34)>0,0,1/NETWORKDAYS(M34,N34,holiday!B$4:B$20)*(IF($S$5<=M34,0,NETWORKDAYS(M34,IF($S$5>N34,N34,$S$5),holiday!B$4:B$20)))) -> 1 | U34: 0 | V34: 0.25 | W34: =R34*V34 -> 0.25 | X34: =U34*V34 -> 0 | Y34: =IF(N34-$S$5<=0,0,CONCATENATE(NETWORKDAYS($S$5,N34,holiday!$B$4:$B$20))) -> 0 | Z34: =IF(SUM(W34:X34)>0,(X34-W34)/V34,0) -> -1
B35: 26 | C35: Project 2.3.2 | D35: 3 | H35: 가맹점 추천 서비스 | L35: =CONCATENATE(NETWORKDAYS(M35,N35,holiday!B$4:B$20),"일") -> 6일 | M35: =MIN(M36:M38) -> 46104 | N35: =MAX(N36:N38) -> 46111 | O35: 한국조폐공사 | P35: 핑거 | Q35: 유효준 | R35: =SUM(W36:W41) -> 0.65 | U35: =SUM(X36:X41) -> 0 | V35: 0.15 | W35: =R35*V35 -> 0.0975 | X35: =U35*V35 -> 0 | Y35: =IF(N35-$S$5<=0,0,CONCATENATE(NETWORKDAYS($S$5,N35,holiday!$B$4:$B$20))) -> 0 | Z35: =IF(SUM(W35:X35)>0,(X35-W35)/V35,0) -> -0.65
B36: 27 | C36: Project 2.3.2.1 | D36: 5 | I36: 가맹점 추천(사장님 혜택 등) 서비스, BO 테이블 설계 | L36: =CONCATENATE(NETWORKDAYS(M36,N36,holiday!B$4:B$20),"일") -> 6일 | M36: 46104 | N36: 46111 | O36: 한국조폐공사 | P36: 핑거 | Q36: 유효준 | R36: =IF(COUNTBLANK(M36:N36)>0,0,1/NETWORKDAYS(M36,N36,holiday!B$4:B$20)*(IF($S$5<=M36,0,NETWORKDAYS(M36,IF($S$5>N36,N36,$S$5),holiday!B$4:B$20)))) -> 1 | U36: 0 | V36: 0.2 | W36: =R36*V36 -> 0.2 | X36: =U36*V36 -> 0 | Y36: =IF(N36-$S$5<=0,0,CONCATENATE(NETWORKDAYS($S$5,N36,holiday!$B$4:$B$20))) -> 0 | Z36: =IF(SUM(W36:X36)>0,(X36-W36)/V36,0) -> -1
B37: 28 | C37: Project 2.3.2.2 | D37: 5 | I37: 가맹점 추천(사장님 혜택 등) 서비스, BO API 설계 | L37: =CONCATENATE(NETWORKDAYS(M37,N37,holiday!B$4:B$20),"일") -> 6일 | M37: 46104 | N37: 46111 | O37: 한국조폐공사 | P37: 핑거 | Q37: 유효준 | R37: =IF(COUNTBLANK(M37:N37)>0,0,1/NETWORKDAYS(M37,N37,holiday!B$4:B$20)*(IF($S$5<=M37,0,NETWORKDAYS(M37,IF($S$5>N37,N37,$S$5),holiday!B$4:B$20)))) -> 1 | U37: 0 | V37: 0.2 | W37: =R37*V37 -> 0.2 | X37: =U37*V37 -> 0 | Y37: =IF(N37-$S$5<=0,0,CONCATENATE(NETWORKDAYS($S$5,N37,holiday!$B$4:$B$20))) -> 0 | Z37: =IF(SUM(W37:X37)>0,(X37-W37)/V37,0) -> -1
B38: 29 | C38: Project 2.3.2.3 | D38: 5 | I38: 가맹점 추천(사장님 혜택 등) 서비스, BO 화면 설계 | L38: =CONCATENATE(NETWORKDAYS(M38,N38,holiday!B$4:B$20),"일") -> 6일 | M38: 46104 | N38: 46111 | O38: 한국조폐공사 | P38: 핑거 | Q38: 유효준 | R38: =IF(COUNTBLANK(M38:N38)>0,0,1/NETWORKDAYS(M38,N38,holiday!B$4:B$20)*(IF($S$5<=M38,0,NETWORKDAYS(M38,IF($S$5>N38,N38,$S$5),holiday!B$4:B$20)))) -> 1 | U38: 0 | V38: 0.25 | W38: =R38*V38 -> 0.25 | X38: =U38*V38 -> 0 | Y38: =IF(N38-$S$5<=0,0,CONCATENATE(NETWORKDAYS($S$5,N38,holiday!$B$4:$B$20))) -> 0 | Z38: =IF(SUM(W38:X38)>0,(X38-W38)/V38,0) -> -1
B39: 30 | C39: Project 2.3.2.4 | D39: 5 | I39: 업종 세분화, 공통뱃지, 단순혜택 프로모션 이벤트 서비스, BO 테이블 설계 | L39: =CONCATENATE(NETWORKDAYS(M39,N39,holiday!B$4:B$20),"일") -> 29일 | M39: 46162 | N39: 46203 | O39: 한국조폐공사 | P39: 핑거 | Q39: 유효준 | R39: =IF(COUNTBLANK(M39:N39)>0,0,1/NETWORKDAYS(M39,N39,holiday!B$4:B$20)*(IF($S$5<=M39,0,NETWORKDAYS(M39,IF($S$5>N39,N39,$S$5),holiday!B$4:B$20)))) -> 0 | U39: 0 | V39: 0.1 | W39: =R39*V39 -> 0 | X39: =U39*V39 -> 0 | Y39: =IF(N39-$S$5<=0,0,CONCATENATE(NETWORKDAYS($S$5,N39,holiday!$B$4:$B$20))) -> 58 | Z39: =IF(SUM(W39:X39)>0,(X39-W39)/V39,0) -> 0
B40: 31 | C40: Project 2.3.2.5 | D40: 5 | I40: 업종 세분화, 공통뱃지, 단순혜택 프로모션 이벤트 서비스, BO API 설계 | L40: =CONCATENATE(NETWORKDAYS(M40,N40,holiday!B$4:B$20),"일") -> 29일 | M40: 46162 | N40: 46203 | O40: 한국조폐공사 | P40: 핑거 | Q40: 유효준 | R40: =IF(COUNTBLANK(M40:N40)>0,0,1/NETWORKDAYS(M40,N40,holiday!B$4:B$20)*(IF($S$5<=M40,0,NETWORKDAYS(M40,IF($S$5>N40,N40,$S$5),holiday!B$4:B$20)))) -> 0 | U40: 0 | V40: 0.1 | W40: =R40*V40 -> 0 | X40: =U40*V40 -> 0 | Y40: =IF(N40-$S$5<=0,0,CONCATENATE(NETWORKDAYS($S$5,N40,holiday!$B$4:$B$20))) -> 58 | Z40: =IF(SUM(W40:X40)>0,(X40-W40)/V40,0) -> 0
B41: 32 | C41: Project 2.3.2.6 | D41: 5 | I41: 업종 세분화, 공통뱃지, 단순혜택 프로모션 이벤트 서비스, BO 화면 설계 | L41: =CONCATENATE(NETWORKDAYS(M41,N41,holiday!B$4:B$20),"일") -> 29일 | M41: 46162 | N41: 46203 | O41: 한국조폐공사 | P41: 핑거 | Q41: 유효준 | R41: =IF(COUNTBLANK(M41:N41)>0,0,1/NETWORKDAYS(M41,N41,holiday!B$4:B$20)*(IF($S$5<=M41,0,NETWORKDAYS(M41,IF($S$5>N41,N41,$S$5),holiday!B$4:B$20)))) -> 0 | U41: 0 | V41: 0.15 | W41: =R41*V41 -> 0 | X41: =U41*V41 -> 0 | Y41: =IF(N41-$S$5<=0,0,CONCATENATE(NETWORKDAYS($S$5,N41,holiday!$B$4:$B$20))) -> 58 | Z41: =IF(SUM(W41:X41)>0,(X41-W41)/V41,0) -> 0
B42: 33 | C42: Project 2.4 | D42: 2 | G42: 온누리상품권 가맹 관리시스템 | L42: =CONCATENATE(NETWORKDAYS(M42,N42,holiday!B$4:B$20),"일") -> 30일 | M42: =MIN(M43,M46,M52) -> 46101 | N42: =MAX(N43,N46,N52) -> 46142 | O42: 한국조폐공사 | P42: 더큰소프트 | Q42: 신용철 | R42: =SUM(W43,W46,W52) -> 0.18181818 | U42: =SUM(X43,X46,X52) -> 0.045 | V42: 0.25 | W42: =R42*V42 -> 0.045454545 | X42: =U42*V42 -> 0.01125 | Y42: =IF(N42-$S$5<=0,0,CONCATENATE(NETWORKDAYS($S$5,N42,holiday!$B$4:$B$20))) -> 17 | Z42: =IF(SUM(W42:X42)>0,(X42-W42)/V42,0) -> -0.13681818
B43: 34 | C43: Project 2.4.1 | D43: 3 | H43: 현황 및 요구사항 분석 | L43: =CONCATENATE(NETWORKDAYS(M43,N43,holiday!B$4:B$20),"일") -> 8일 | M43: =MIN(M44,M45) -> 46101 | N43: =MAX(N44,N45) -> 46112 | O43: 한국조폐공사 | P43: 더큰소프트 | Q43: 신용철 | R43: =SUM(W44:W45) -> 1 | U43: =SUM(X44:X45) -> 0.45 | V43: 0.1 | W43: =R43*V43 -> 0.1 | X43: =U43*V43 -> 0.045 | Y43: =IF(N43-$S$5<=0,0,CONCATENATE(NETWORKDAYS($S$5,N43,holiday!$B$4:$B$20))) -> 0 | Z43: =IF(SUM(W43:X43)>0,(X43-W43)/V43,0) -> -0.55
B44: 35 | C44: Project 2.4.1.1 | D44: 4 | I44: 가맹점 관리 AS-IS 시스템 분석 | L44: =CONCATENATE(NETWORKDAYS(M44,N44,holiday!B$4:B$20),"일") -> 8일 | M44: 46101 | N44: 46112 | O44: 한국조폐공사 | P44: 더큰소프트 | Q44: 신용철 | R44: =IF(COUNTBLANK(M44:N44)>0,0,1/NETWORKDAYS(M44,N44,holiday!B$4:B$20)*(IF($S$5<=M44,0,NETWORKDAYS(M44,IF($S$5>N44,N44,$S$5),holiday!B$4:B$20)))) -> 1 | U44: 0.45 | V44: 0.5 | W44: =R44*V44 -> 0.5 | X44: =U44*V44 -> 0.225 | Y44: =IF(N44-$S$5<=0,0,CONCATENATE(NETWORKDAYS($S$5,N44,holiday!$B$4:$B$20))) -> 0 | Z44: =IF(SUM(W44:X44)>0,(X44-W44)/V44,0) -> -0.55 | AA44: 화면 설계, 단위테스트, 프로그램목록
...

Sheet 시스템별 진척관리
D4: 구분 | E4: 분석/설계 | H4: 개발 | K4: 테스트 | N4: 이행안정화 | Q4: 전체(진척율)
E5: 실적 | F5: 계획 | G5: 진척율 | H5: 실적 | I5: 계획 | J5: 진척율 | K5: 실적 | L5: 계획 | M5: 진척율 | N5: 실적 | O5: 계획 | P5: 진척율
D6: 핑거 | E6: {=SUMPRODUCT((WBS_선행개발!$D$19:$D$103=2)*(WBS_선행개발!$P$19:$P$103="핑거")*WBS_선행개발!$X$19:$X$103)*WBS_선행개발!$V$18} -> 0.002325 | F6: {=SUMPRODUCT((WBS_선행개발!$D$19:$D$103=2)*(WBS_선행개발!$P$19:$P$103="핑거")*WBS_선행개발!$W$19:$W$103)*WBS_선행개발!$V$18} -> 0.0373125 | G6: =IFERROR(E6/F6,0) -> 0.062311558 | H6: {=SUMPRODUCT((WBS_선행개발!$D$105:$D$220=2)*(WBS_선행개발!$P$105:$P$220="핑거")*WBS_선행개발!$X$105:$X$220)*WBS_선행개발!$V$104} -> 0 | I6: {=SUMPRODUCT((WBS_선행개발!$D$105:$D$220=2)*(WBS_선행개발!$P$105:$P$220="핑거")*WBS_선행개발!$W$105:$W$220)*WBS_선행개발!$V$104} -> 0.01172581 | J6: =IFERROR(H6/I6,0) -> 0 | K6: {=SUMPRODUCT((WBS_선행개발!$D$222:$D$261=2)*(WBS_선행개발!$P$222:$P$261="핑거")*WBS_선행개발!$X$222:$X$261)*WBS_선행개발!$V$221} -> 0 | L6: {=SUMPRODUCT((WBS_선행개발!$D$222:$D$261=2)*(WBS_선행개발!$P$222:$P$261="핑거")*WBS_선행개발!$W$222:$W$261)*WBS_선행개발!$V$221} -> 0 | M6: =IFERROR(K6/L6,0) -> 0 | N6: {=SUMPRODUCT((WBS_선행개발!$D$263:$D$285=2)*(WBS_선행개발!$P$263:$P$285="핑거")*WBS_선행개발!$X$263:$X$285)*WBS_선행개발!$V$262} -> 0 | O6: {=SUMPRODUCT((WBS_선행개발!$D$263:$D$285=2)*(WBS_선행개발!$P$263:$P$285="핑거")*WBS_선행개발!$W$263:$W$285)*WBS_선행개발!$V$262} -> 0 | P6: =IFERROR(N6/O6,0) -> 0 | Q6: =IFERROR((E6+H6+K6+N6)/(F6+I6+L6+O6),0) -> 0.047411911
D7: 시루정보 | E7: {=SUMPRODUCT((WBS_선행개발!$D$19:$D$103=2)*(WBS_선행개발!$P$19:$P$103="시루정보")*WBS_선행개발!$X$19:$X$103)*WBS_선행개발!$V$18} -> 0.07275 | F7: {=SUMPRODUCT((WBS_선행개발!$D$19:$D$103=2)*(WBS_선행개발!$P$19:$P$103="시루정보")*WBS_선행개발!$W$19:$W$103)*WBS_선행개발!$V$18} -> 0.075 | G7: =IFERROR(E7/F7,0) -> 0.97 | H7: {=SUMPRODUCT((WBS_선행개발!$D$105:$D$220=2)*(WBS_선행개발!$P$105:$P$220="시루정보")*WBS_선행개발!$X$105:$X$220)*WBS_선행개발!$V$104} -> 0 | I7: {=SUMPRODUCT((WBS_선행개발!$D$105:$D$220=2)*(WBS_선행개발!$P$105:$P$220="시루정보")*WBS_선행개발!$W$105:$W$220)*WBS_선행개발!$V$104} -> 0.0084 | J7: =IFERROR(H7/I7,0) -> 0 | K7: {=SUMPRODUCT((WBS_선행개발!$D$222:$D$261=2)*(WBS_선행개발!$P$222:$P$261="시루정보")*WBS_선행개발!$X$222:$X$261)*WBS_선행개발!$V$221} -> 0 | L7: {=SUMPRODUCT((WBS_선행개발!$D$222:$D$261=2)*(WBS_선행개발!$P$222:$P$261="시루정보")*WBS_선행개발!$W$222:$W$261)*WBS_선행개발!$V$221} -> 0 | M7: =IFERROR(K7/L7,0) -> 0 | N7: {=SUMPRODUCT((WBS_선행개발!$D$263:$D$285=2)*(WBS_선행개발!$P$263:$P$285="시루정보")*WBS_선행개발!$X$263:$X$285)*WBS_선행개발!$V$262} -> 0 | O7: {=SUMPRODUCT((WBS_선행개발!$D$263:$D$285=2)*(WBS_선행개발!$P$263:$P$285="시루정보")*WBS_선행개발!$W$263:$W$285)*WBS_선행개발!$V$262} -> 0 | P7: =IFERROR(N7/O7,0) -> 0 | Q7: =IFERROR((E7+H7+K7+N7)/(F7+I7+L7+O7),0) -> 0.87230216
D8: 더큰소프트 | E8: {=SUMPRODUCT((WBS_선행개발!$D$19:$D$103=2)*(WBS_선행개발!$P$19:$P$103="더큰소프트")*WBS_선행개발!$X$19:$X$103)*WBS_선행개발!$V$18} -> 0.003375 | F8: {=SUMPRODUCT((WBS_선행개발!$D$19:$D$103=2)*(WBS_선행개발!$P$19:$P$103="더큰소프트")*WBS_선행개발!$W$19:$W$103)*WBS_선행개발!$V$18} -> 0.013636364 | G8: =IFERROR(E8/F8,0) -> 0.2475 | H8: {=SUMPRODUCT((WBS_선행개발!$D$105:$D$220=2)*(WBS_선행개발!$P$105:$P$220="더큰소프트")*WBS_선행개발!$X$105:$X$220)*WBS_선행개발!$V$104} -> 0 | I8: {=SUMPRODUCT((WBS_선행개발!$D$105:$D$220=2)*(WBS_선행개발!$P$105:$P$220="더큰소프트")*WBS_선행개발!$W$105:$W$220)*WBS_선행개발!$V$104} -> 0.015443478 | J8: =IFERROR(H8/I8,0) -> 0 | K8: {=SUMPRODUCT((WBS_선행개발!$D$222:$D$261=2)*(WBS_선행개발!$P$222:$P$261="더큰소프트")*WBS_선행개발!$X$222:$X$261)*WBS_선행개발!$V$221} -> 0 | L8: {=SUMPRODUCT((WBS_선행개발!$D$222:$D$261=2)*(WBS_선행개발!$P$222:$P$261="더큰소프트")*WBS_선행개발!$W$222:$W$261)*WBS_선행개발!$V$221} -> 0 | M8: =IFERROR(K8/L8,0) -> 0 | N8: {=SUMPRODUCT((WBS_선행개발!$D$263:$D$285=2)*(WBS_선행개발!$P$263:$P$285="더큰소프트")*WBS_선행개발!$X$263:$X$285)*WBS_선행개발!$V$262} -> 0 | O8: {=SUMPRODUCT((WBS_선행개발!$D$263:$D$285=2)*(WBS_선행개발!$P$263:$P$285="더큰소프트")*WBS_선행개발!$W$263:$W$285)*WBS_선행개발!$V$262} -> 0 | P8: =IFERROR(N8/O8,0) -> 0 | Q8: =IFERROR((E8+H8+K8+N8)/(F8+I8+L8+O8),0) -> 0.11605978

Sheet holiday
B2: 공휴일
B3: Date | C3: Remarks
B4: 46023 | C4: 새해
B5: 46069 | C5: 설날
B6: 46070 | C6: 설날
B7: 46071 | C7: 설날
B8: 46082 | C8: 31운동
B9: 46083 | C9: 31운동
B10: 46147 | C10: 어린이날
B11: 46166 | C11: 부처 오신날
B12: 46167 | C12: 부처 오신날
B13: 46179 | C13: 현충일
B14: 46249 | C14: 광복절
B15: 46251 | C15: 광복절
... B23: 46381 | C23: 크리스마스
